Workbook

Sheet 🎓 UNI-DATASET
A1: 🎓 University Data - Curriculum Skills Dataset
A2: University | B2: Major | C2: Course Code | D2: Course Name | E2: Skill
A3: Al-Zaytoonah University of Jordan | B3: Accounting | C3: 0502110 | D3: Principles of Accounting (1) | E3: Accounting Cycle
A4: Al-Zaytoonah University of Jordan | B4: Accounting | C4: 0502110 | D4: Principles of Accounting (1) | E4: Financial Statements
A5: Al-Zaytoonah University of Jordan | B5: Accounting | C5: 0502110 | D5: Principles of Accounting (1) | E5: Financial Accounting Principles
A6: Al-Zaytoonah University of Jordan | B6: Accounting | C6: 0502111 | D6: Principles of Accounting | E6: Financial Accounting Principles
A7: Al-Zaytoonah University of Jordan | B7: Accounting | C7: 0502213 | D7: Intermediate Accounting (1) | E7: Cash Flow Management
A8: Al-Zaytoonah University of Jordan | B8: Accounting | C8: 0502213 | D8: Intermediate Accounting (1) | E8: Inventory Accounting
A9: Al-Zaytoonah University of Jordan | B9: Accounting | C9: 0502213 | D9: Intermediate Accounting (1) | E9: Intermediate Accounting
A10: Al-Zaytoonah University of Jordan | B10: Accounting | C10: 0502214 | D10: Intermediate Accounting (2) | E10: Depreciation Accounting
A11: Al-Zaytoonah University of Jordan | B11: Accounting | C11: 0502214 | D11: Intermediate Accounting (2) | E11: Intermediate Accounting
A12: Al-Zaytoonah University of Jordan | B12: Accounting | C12: 0502321 | D12: Financial Statement Analysis | E12: Financial Statement Analysis
A13: Al-Zaytoonah University of Jordan | B13: Accounting | C13: 0502321 | D13: Financial Statement Analysis | E13: Financial Statements
... A1147: University of Petra | B1147: Software Engineering | C1147: 603496 | D1147: Software Engineering CASE Tools | E1147: Software Engineering Principles

Sheet 🎓UNI-SUMMARY
A1: 🎓 University Skill Intelligence Summary | Jordan Academic Dataset
A2: DATASET OVERVIEW
A3: 🏫 Universities | E3: 🎓 Majors | J3: 📋 Total Records | O3: 📊 Overall Unique Skills | T3: 📚 Total Distinct Courses | X3: 📈 Core Shared Skills
A4: 3 | E4: 8 | J4: 1145 | O4: 369 | T4: 506 | X4: 42
A5: ━━━━━━━━━━━━ | E5: ━━━━━━━━━━━━ | J5: ━━━━━━━━━━━━ | O5: ━━━━━━━━━━━━ | T5: ━━━━━━━ | X5: ━━━━━━━━━━━━
A8: 📊 Snapshot-of University Curriculum Dataset | H8: . | J8: 🔗 Shared Skills and Unique Skills by University | T8: 📋 Data Quality Report
T9: Check | W9: UOP | X9: PSUT | Y9: ZUJ | Z9: Status
A10: Metric | C10: Petra | D10: PSUT | E10: ZUJ | F10: Total | J10: Overlap ↓ vs → | L10: UOP | N10: PSUT | P10: ZUJ | T10: Null Skills | W10: 0 | X10: 0 | Y10: 0 | Z10: ✅ Clean
A11: Majors Offered | C11: 8 | D11: 7 | E11: 8 | F11: =SUM(C11:E11) -> 23 | J11: UOP | L11: 269 | N11: 107 | P11: 71 | T11: Null Courses | W11: 0 | X11: 0 | Y11: 0 | Z11: ✅ Clean
A12: Total Courses | C12: 209 | D12: 147 | E12: 150 | F12: =SUM(C12:E12) -> 506 | J12: PSUT | L12: 107 | N12: 164 | P12: 50 | T12: Null Universities | W12: 0 | X12: 0 | Y12: 0 | Z12: ✅ Clean
A13: Total Records | C13: 710 | D13: 259 | E13: 176 | F13: =SUM(C13:E13) -> 1145 | J13: ZUJ | L13: 71 | N13: 50 | P13: 122 | T13: BI Major Present | W13: Yes | X13: No | Y13: Yes | Z13: ⚠ PSUT missing BI
J14: ✅ 42 core skills are shared by ALL 3 universities, representing the common curriculum foundation across UOP, PSUT, and ZUJ. | T14: University-Level Unique Skills | W14: 269 | X14: 164 | Y14: 122 | Z14: 📊 Overlaps exist
A17: 🏆 UNIVERSITY PROFILE SUMMARY
A19: 🎓 Petra | J19: 🎓 PSUT | T19: 🎓 Zaytoonah
A21: 8 majors _ including Business Intelligence | J21: 7 majors — does NOT offer Business Intelligence | T21: 8 majors including Business Intelligence
A22: Leads in extracted skill entries in the cleaned dataset, mainly due to detailed course descriptions. | J22: Strong technical coverage in Computer Science, Cybersecurity, Data Science & AI, and Software Engineering. | T22: Broad major coverage, with fewer extracted skill entries under the conservative cleaning method
A23: Courses: 209 | Records: 710 | Unique Skills: 269 | J23: Courses: 147 | Records: 259 | Unique Skills: 164 | T23: Courses: 150 | Records: 176 | Unique Skills: 122
A26: 📈 Visual Analytics Dashboard - University Skill Intelligence - Jordan | AI26: charts table
AI28: Skill Entries by Major | AN28: Courses by Major
AI30: Major | AJ30: UOP | AK30: PSUT | AL30: ZUJ | AN30: Major | AO30: UOP | AP30: PSUT | AQ30: ZUJ
AI31: Accounting | AJ31: 96 | AK31: 34 | AL31: 39 | AN31: Accounting | AO31: 29 | AP31: 18 | AQ31: 16
AI32: Bus. Admin | AJ32: 114 | AK32: 68 | AL32: 48 | AN32: Bus. Admin | AO32: 42 | AP32: 44 | AQ32: 48
AI33: Bus. Intel. | AJ33: 128 | AK33: 0 | AL33: 25 | AN33: Bus. Intel. | AO33: 36 | AP33: 0 | AQ33: 24
AI34: Comp. Sci. | AJ34: 8 | AK34: 34 | AL34: 28 | AN34: Comp. Sci. | AO34: 3 | AP34: 15 | AQ34: 28
AI35: Cybersecurity | AJ35: 42 | AK35: 19 | AL35: 22 | AN35: Cybersecurity | AO35: 18 | AP35: 9 | AQ35: 20
AI36: Data Sci. & AI | AJ36: 100 | AK36: 24 | AL36: 8 | AN36: Data Sci. & AI | AO36: 25 | AP36: 21 | AQ36: 8
AI37: Marketing | AJ37: 158 | AK37: 41 | AL37: 4 | AN37: Marketing | AO37: 32 | AP37: 21 | AQ37: 4
AI38: SW | AJ38: 64 | AK38: 39 | AL38: 2 | AN38: SW | AO38: 24 | AP38: 19 | AQ38: 2
AK40: =SUM(AJ31:AJ38,AK31:AK38,AL31:AL38) -> 1145 | AP40: =SUM(AO31:AO38,AP31:AP38,AQ31:AQ38) -> 506
A55: Petra has the highest extracted skill entries in most majors, especially Marketing, Business Intelligence, and Data Science & AI. This reflects the number of explicit skills extracted from course information, not necessarily curriculum quality. | P55: Business Administration has the highest course coverage across all three universities, while PSUT has no Business Intelligence major in this dataset.

Sheet 📋 Normalized Skills List
A1: 📋 Normalized Skills List-unique
A2: University | B2: Major | C2: Course Code | D2: Course Name | E2: Skill
A3: Al-Zaytoonah University of Jordan | B3: Accounting | C3: 502110 | D3: Principles of Accounting (1) | E3: accounting cycle
A4: Al-Zaytoonah University of Jordan | B4: Accounting | C4: 502110 | D4: Principles of Accounting (1) | E4: financial statements
A5: Al-Zaytoonah University of Jordan | B5: Accounting | C5: 502110 | D5: Principles of Accounting (1) | E5: financial accounting principles
A6: Al-Zaytoonah University of Jordan | B6: Accounting | C6: 502213 | D6: Intermediate Accounting (1) | E6: cash flow management
A7: Al-Zaytoonah University of Jordan | B7: Accounting | C7: 502213 | D7: Intermediate Accounting (1) | E7: inventory accounting
A8: Al-Zaytoonah University of Jordan | B8: Accounting | C8: 502213 | D8: Intermediate Accounting (1) | E8: intermediate accounting
A9: Al-Zaytoonah University of Jordan | B9: Accounting | C9: 502214 | D9: Intermediate Accounting (2) | E9: depreciation accounting
A10: Al-Zaytoonah University of Jordan | B10: Accounting | C10: 502321 | D10: Financial Statement Analysis | E10: financial statement analysis
A11: Al-Zaytoonah University of Jordan | B11: Accounting | C11: 502322 | D11: Accounting Theory | E11: accounting theory
A12: Al-Zaytoonah University of Jordan | B12: Accounting | C12: 502322 | D12: Accounting Theory | E12: revenue recognition
A13: Al-Zaytoonah University of Jordan | B13: Accounting | C13: 502331 | D13: Introduction to Cost Accounting | E13: cost accounting
A14: Al-Zaytoonah University of Jordan | B14: Accounting | C14: 502331 | D14: Introduction to Cost Accounting | E14: income statement preparation
... A371: University of Petra | B371: Software Engineering | C371: 603491 | D371: Software Configuration Management | E371: software configuration management

Sheet 💼JOB-DATASET
A1: 💼 MENA -JOB DATASET
A2: # | B2: Job Title | C2: Company | D2: Location | E2: Sector | F2: Source | G2: Experience Level | H2: Date Posted | I2: Job Description | J2: Skills | K2: URL | L2: Skill_Count
A3: 1 | B3: UAE National -Insurance Assistant- Property Underwriting | Financial Services| Orient Insurance PJSC | C3: Al Futtaim Group | D3: UAE | E3: Accounting | F3: Bayt | G3: Mid-level | H3: 2026-04-14 | I3: Job description Job description The successful candidates will be responsible to organise, analyse statistical data, and maintain systematic computerized records related to premiums, which will ensure an efficient control on the underwriting of the company’s business. What you will do Managing the existing renewal book, with review of accounts well in advance of renewal date’s to ensure the profitability of the book Handle day to day underwriting functions in a prompt manner by adhering to the prescribed guidelines and procedures Monitor the progress of risk management of the clients arrange periodic risk surveys Ability to scrutinize new submissions received and analyze the risk in line with Underwriting Guidelines in support of underwriting decisions Working closely with different business channels in securing new businesses as well as retention of existing portfolios Assist in the preparation of management reports, premium and claims statistics, in order to facilitate Management’s review and decision making actions Must provide highest standard of customer experience to all business partners | J3: Claims Statistics, Premium Statistics, Risk Management, Underwriting, Data Analysis, Statistical Analysis, Customer Experience, Organizational Skills, Accounting Principles | K3: https://www.bayt.com/en/uae/jobs/uae-national-insurance-assistant-property-underwriting-financial-services-orient-insurance-pjsc-5449272/ | L3: =IF(TRIM(J3)="",0,LEN(J3)-LEN(SUBSTITUTE(J3,",",""))+1) -> 9
A4: 2 | B4: Accounts Payable Accountant | C4: CARMA | D4: UAE | E4: Accounting | F4: Bayt | G4: Mid-level | H4: 2026-04-21 | I4: Job description CARMA is a globally-trusted media intelligence leader with decades of experience helping PR and communications professionals monitor what matters, measure what’s meaningful, and demonstrate the value of their work. We combine cutting-edge technology, including AI-enabled media monitoring across print, online, broadcast, and social channels in 100+ languages - with deep human expertise to deliver actionable insights that inform strategy and drive business-critical decisions. With a diverse global team supporting thousands of organisations worldwide, CARMA empowers partners to turn complex media data into clarity and context, elevate the impact of earned media, and deepen understanding of stakeholder influence across markets. Role Overview: The Accounts Payable Accountant will be responsible for managing the company’s payables function with accuracy, efficiency, and strong internal control compliance. This role supports financial integrity by ensuring timely processing of vendor invoices, reconciliation of accounts, and adherence to company policies while contributing to smooth financial operations across CARMA’s global business. Role & Responsibilities: Process vendor invoices, expense claims, and payment requests accurately and in a timely manner. Verify invoice documentation, approvals, coding, and compliance with company policies and contractual terms. Maintain vendor records and manage supplier communications professionally and efficiently. Prepare payment runs (bank transfers, cheques, or other payment methods) according to agreed schedules. Reconcile vendor statements and resolve discrepancies promptly. Assist with month-end closing activities including accruals, reconciliations, and reporting. Support audits by providing required documentation and explanations. Ensure compliance with financial controls, tax requirements, and accounting standards. Collaborate with procurement, finance, and operational teams globally to ensure smooth financial workflows. Identify opportunities for process improvements and automation within accounts payable functions. Bachelor’s degree in Accounting, Finance, or a related field. 2–4 years of relevant experience in accounts payable or general accounting, preferably in a corporate or multinational environment. Solid understanding of accounting principles and internal controls. Experience with ERP or accounting systems (e. g., MS Dynamics or similar). Proficiency in Microsoft Excel and MS Office applications. Strong attention to detail with the ability to meet deadlines in a fast-paced environment. High level of integrity and ability to handle confidential information. | J4: Accounts Payable, Account Reconciliation, Month-End Close, Tax Compliance, Audit Support, Internal Controls, Invoice Processing, Supplier Reconciliation, Microsoft Excel, Microsoft Office, Microsoft Dynamics, ERP Systems, AI/ML, Standards Management, Technical Writing, Vendor Management, Collaboration, Attention to Detail, Problem Solving, Confidentiality, Deadline Management, Accounting Principles | K4: https://www.bayt.com/en/uae/jobs/accounts-payable-accountant-74156557/ | L4: =IF(TRIM(J4)="",0,LEN(J4)-LEN(SUBSTITUTE(J4,",",""))+1) -> 22
A5: 3 | B5: Junior Accountant - Automotive Parts Group | C5: Prestige Global Trading LLC | D5: UAE | E5: Accounting | F5: Bayt | G5: Junior | H5: 2026-03-31 | I5: Job description Job Title Inter-Branch Accountant – Automotive Parts Group Location Head Office – Umm Ramool, Dubai Reporting To Chief Accountant Role Summary You will be responsible for inter-branch accounting, reconciliations, and internal controls across multiple car-parts retail and wholesale branches. This is a hands-on execution role, not advisory. Your job is to make sure numbers between branches match, stock movements are accounted for, cash is traceable, and nothing “disappears” in excuses or spreadsheets. If inter-company balances don’t tie, that’s your problem to fix. Key Responsibilities Inter-Branch & Inter-Company Accounting Manage and reconcile inter-branch transactions (stock transfers, expenses, internal invoices, allocations). Ensure all inter-company balances match and are cleared monthly. Identify, investigate, and resolve discrepancies without escalation unless necessary. Reconciliations Daily / weekly reconciliation of: Bank accounts Cash collections Inter-branch balances Supplier and internal ledgers Ensure no unreconciled balances are carried forward casually. Inventory & Cost Control Reconcile stock movements between branches and warehouse. Work closely with operations to ensure: GRNs, transfers, and sales match accounting records No negative stock, unexplained variances, or valuation errors Reporting & Discipline Prepare monthly inter-branch reconciliation reports for the Chief Accountant. Flag recurring issues, weak controls, or sloppy processes — with solutions, not complaints. Support VAT workings related to inter-company transactions (UAE VAT knowledge required). Compliance & Process Follow company accounting procedures strictly. Help enforce documentation discipline across branches (no paperwork = no posting). Support audits and internal reviews when required. Salary offered 3500 AED | J5: Account Reconciliation, VAT, Audit Support, Internal Controls, Invoice Processing, Cost Control, Inventory Accounting, Technical Writing, Problem Solving, Accounting Principles | K5: https://www.bayt.com/en/uae/jobs/junior-accountant-automotive-parts-group-5446394/ | L5: =IF(TRIM(J5)="",0,LEN(J5)-LEN(SUBSTITUTE(J5,",",""))+1) -> 10
A6: 4 | B6: Product & Safety Compliance Manager | C6: Parker Connect | D6: UAE | E6: Accounting | F6: Bayt | G6: Managerial | H6: 2026-04-21 | I6: Job description Our client a leading consumer electronic company is looking to hire a Product & Safety Compliance Manager. Job Description Pro-actively working with regulatory authorities to ensure product is complying with the necessary & mandatory requirements Defining product compliance requirements Develop and lead global regulatory strategy Monitoring for emerging trends, policies, regulations and guidelines and Analyze and communicate Advising factories and stakeholders on updates proactively region wise regulations and compliances Maintaining standards library Review regulatory submissions Other Duties Special skills or qualifications : Bachelor's Degree in Commerce / Business Administration, preferably in sales & marketing. Prior work experience with a principal / distributor company is essential. Expertise on products compliance placed in international (Non-EU) markets mainly MEA region Good communication skills (both written and oral) Ability to write technical product information Arabic Speaking | J6: Regulatory Compliance, Product Compliance, Standards Management, Technical Writing, Communication, Arabic Language, Accounting Principles | K6: https://www.bayt.com/en/uae/jobs/product-safety-compliance-manager-51218513/ | L6: =IF(TRIM(J6)="",0,LEN(J6)-LEN(SUBSTITUTE(J6,",",""))+1) -> 7
A7: 5 | B7: Female Accounts Payable Accountant Assistant | C7: SAHAHRA PRINTING PUBLISHING LLC | D7: UAE | E7: Accounting | F7: Bayt | G7: Mid-level | H7: 2026-04-21 | I7: Job description Looking for female accountant to assist on mainly Payables . Key role : Supplier invoices booking in Tally and process payment Employee's Payroll and Expense Petty cash other accounts ledger entries Assist Account Manager Package : 3000k pm benefits : As per UAE Law Visa : Company will provide | J7: Accounts Payable, Payroll, Petty Cash, Invoice Processing, Tally, Accounting Principles | K7: https://www.bayt.com/en/uae/jobs/female-accounts-payable-accountant-assistant-5450188/ | L7: =IF(TRIM(J7)="",0,LEN(J7)-LEN(SUBSTITUTE(J7,",",""))+1) -> 6
A8: 6 | B8: Assistant Accountant | C8: N/A | D8: UAE | E8: Accounting | F8: Bayt | G8: Mid-level | H8: 2026-04-21 | I8: Job description Join our dynamic team as an Assistant Accountant and take the next step in your career within the thriving trading and commodity trading industry. As an integral part of our finance department, you will play a crucial role in ensuring the accuracy and efficiency of our financial operations. This position offers a unique opportunity to deepen your understanding of financial processes while contributing to a fast-paced and rewarding environment. In this role, you will collaborate closely with experienced accountants and financial analysts, gaining invaluable insights into the intricacies of financial reporting, budgeting, and forecasting. We prioritize professional development and provide access to training programs that will enhance your skills and prepare you for future advancement within our organization. Our supportive team culture encourages knowledge sharing and mentorship, ensuring that you are equipped to excel in your career. As you grow with us, you will have the chance to take on more complex tasks and responsibilities, paving the way for your career progression. We believe in recognizing and rewarding talent, and as you demonstrate your capabilities, opportunities for promotion and increased responsibilities will follow. Join us and be part of a company that values your contributions and is committed to your professional growth. Responsibilities:Assist in the preparation of financial statements and reports by gathering data and ensuring accuracy, using accounting software to streamline the process and support informed decision-making. Manage accounts payable and receivable functions, ensuring timely processing of invoices and payments, while maintaining positive relationships with vendors and clients. Reconcile bank statements and accounts regularly to ensure accuracy and identify discrepancies, utilizing analytical skills to resolve issues effectively. Support the budgeting process by providing input on financial data and projections, helping the team to create realistic financial plans that align with company goals. Maintain accurate records of financial transactions in compliance with company policies and accounting standards, ensuring transparency and accountability in all financial dealings. Assist in conducting audits by preparing necessary documentation and providing support to auditors, ensuring that all financial practices meet regulatory requirements. Participate in month-end and year-end closing processes, helping to ensure timely completion of financial reports and compliance with deadlines. Collaborate with other departments to provide financial insights and support for various projects, enhancing cross-functional communication and teamwork. Stay updated on industry trends and changes in accounting regulations, ensuring that the company remains compliant and competitive in the market. | J8: Accounts Payable, Bank Reconciliation, Account Reconciliation, Financial Reporting, Month-End Close, Year-End Close, Budgeting, Forecasting, Audit Support, Invoice Processing, Microsoft Excel, ERP Systems, Regulatory Compliance, Standards Management, Technical Writing, Vendor Management, Collaboration, Attention to Detail, Deadline Management, Accounting Principles | K8: https://www.bayt.com/en/uae/jobs/assistant-accountant-4490880/ | L8: =IF(TRIM(J8)="",0,LEN(J8)-LEN(SUBSTITUTE(J8,",",""))+1) -> 20
A9: 7 | B9: Senior Accountant | C9: Parker Connect | D9: UAE | E9: Accounting | F9: Bayt | G9: Senior | H9: 2026-04-21 | I9: Job description Required a Male Candidate for one of our Client. Candidate must have experience in finance preferably restaurant and hospitality business. | J9: Accounting Principles | K9: https://www.bayt.com/en/uae/jobs/senior-accountant-51218680/ | L9: =IF(TRIM(J9)="",0,LEN(J9)-LEN(SUBSTITUTE(J9,",",""))+1) -> 1
A10: 8 | B10: Accountant | C10: scaffoldgroup | D10: UAE | E10: Accounting | F10: Bayt | G10: Mid-level | H10: 2026-04-12 | I10: Job description Job Summary: An Accountant is required to manage financial records and ensure compliance with regulations while supporting the company’s financial health. The ideal candidate will possess strong analytical skills and a solid understanding of accounting principles. Key Responsibilities: • Prepare and maintain accurate financial records and reports. • Manage accounts payable and receivable. • Reconcile bank statements and general ledger accounts. • Prepare monthly, quarterly, and annual financial statements. • Assist in budgeting and forecasting. • Ensure compliance with financial regulations and standards. • Handle tax filings and ensure timely submission. • Support internal and external audits. • Monitor financial transactions and resolve discrepancies. • Maintain proper documentation of financial activities. Requirements: • Bachelor’s degree in Accounting, Finance, or related field. • Proven experience as an Accountant or similar role. • Strong knowledge of accounting principles and practices. • Proficiency in accounting software (e.g., QuickBooks, SAP, or similar). • Excellent attention to detail and accuracy. • Strong analytical and problem-solving skills. • Good communication and organizational skills. Preferred Qualifications: • Professional certification (e.g., CPA, ACCA, CMA). • Experience with financial reporting and tax regulations. • Familiarity with ERP systems. Work Environment: • Typically office-based, with standard working hours. • May require extended hours during financial closing periods. | J10: Accounts Payable, General Ledger, Bank Reconciliation, Account Reconciliation, Financial Reporting, Budgeting, Forecasting, Tax Compliance, Audit Support, QuickBooks, SAP, ERP Systems, Standards Management, Technical Writing, CPA, ACCA, CMA, Attention to Detail, Problem Solving, Organizational Skills, Deadline Management, Accounting Principles | K10: https://www.bayt.com/en/uae/jobs/%D9%85%D8%AD%D8%A7%D8%B3%D8%A8-5448937/ | L10: =IF(TRIM(J10)="",0,LEN(J10)-LEN(SUBSTITUTE(J10,",",""))+1) -> 22
A11: 9 | B11: Senior Accountant - Project & Revenue Accounting (Temp) | C11: Nathan & Nathan | D11: UAE | E11: Accounting | F11: Bayt | G11: Senior | H11: 2026-04-02 | I11: Job description About the job Senior Accountant - Project & Revenue Accounting (Temp) We are hiring for a Senior Accountant to join a well-established and diversified business group with a strong presence across multiple sectors, including engineering, technology, and services. They are headquartered in Dubai. This is an urgent requirement for a 4–6 months contract (extendable). We are specifically looking for candidates who are currently based in the UAE and available on their own visa. The preferred candidate would be a CA or semi-CA-qualified accountant. Key Responsibilities Project & Revenue Accounting Manage revenue and cost recognition in line with accounting standards and company policies Post journal entries related to project accounting, accruals, and adjustments Track and reconcile unbilled revenue and deferred income Record manpower costs based on timesheets and project allocation Financial Close & Reporting Support month-end close activities and ensure timely reporting Perform GL reviews and variance analysis against budgets Maintain and reconcile balance sheet schedules Tax & Compliance Handle VAT and WHT calculations, filings, and documentation Ensure compliance with local regulations and support during audits Accounts Payable Oversee invoice validation (3-way matching), processing, and vendor payments Monitor vendor aging and perform supplier reconciliations Provisions & Inventory Post amortization entries and manage provisions (inventory, bad debts, etc.) Monitor inventory aging and ensure accurate valuation Requirements Bachelor's degree in Accounting/Finance (CA Inter / Semi-qualified CA preferred) 5–10 years of relevant experience in accounting, preferably in project/service-based industries Strong knowledge of revenue recognition, VAT, and financial controls Hands-on experience with ERP systems (Oracle, SAP, Microsoft Dynamics, JD Edwards) Advanced Excel skills (knowledge of Power Query is an advantage) Strong analytical mindset with attention to detail Additional Information Contract Duration: 4–6 months (extendable) Availability: Immediate joiners preferred Visa Requirement: Candidates must be on their own visa | J11: Accounts Payable, General Ledger, Account Reconciliation, Month-End Close, Budgeting, VAT, WHT, Audit Support, Internal Controls, Invoice Processing, Supplier Reconciliation, Cost Control, Revenue Recognition, Inventory Accounting, Microsoft Excel, Power Query, SAP, Oracle ERP, Microsoft Dynamics, JD Edwards, ERP Systems, Standards Management, Technical Writing, CA, Vendor Management, Attention to Detail, Deadline Management, Accounting Principles | K11: https://www.bayt.com/en/uae/jobs/senior-accountant-project-revenue-accounting-temp-74360748/ | L11: =IF(TRIM(J11)="",0,LEN(J11)-LEN(SUBSTITUTE(J11,",",""))+1) -> 28
A12: 10 | B12: Senior Accountant | C12: STAR SERVICES LLC | D12: UAE | E12: Accounting | F12: Bayt | G12: Senior | H12: 2026-04-21 | I12: Job description About the job Senior Accountant Job Title: Senior Accountant Location: Abu Dhabi Job Purpose: Responsible for managing financial accounting, reporting, and compliance for a holding company. The role requires strong knowledge of accounting principles, ERP systems, and financial controls to ensure accurate and timely reporting. Key Responsibilities: Prepare and review financial statements, reports, and reconciliations. Manage accounts payable, receivable, and general ledger activities. Ensure compliance with accounting standards and regulatory requirements. Monitor budgets, forecasts, and cash flow management. Support audits and liaise with external auditors. Implement and optimize accounting software and ERP systems. Qualifications & Skills: Bachelors degree in Accounting, Finance, or related field. Minimum 5+ years accounting experience, preferably in a holding company. Strong proficiency in accounting software and ERP systems. Excellent analytical, problem-solving, and reporting skills. Good communication and organizational abilities. | J12: Accounts Payable, General Ledger, Account Reconciliation, Financial Reporting, Budgeting, Forecasting, Audit Support, Internal Controls, ERP Systems, Regulatory Compliance, Standards Management, Problem Solving, Deadline Management, Accounting Principles | K12: https://www.bayt.com/en/uae/jobs/senior-accountant-73831025/ | L12: =IF(TRIM(J12)="",0,LEN(J12)-LEN(SUBSTITUTE(J12,",",""))+1) -> 14
A13: 11 | B13: Senior Accountant | C13: Michael Page | D13: UAE | E13: Accounting | F13: Bayt | G13: Senior | H13: 2026-04-21 | I13: Job description This role sits at the heart of a complex, multi‑entity finance function and will lead the full accounting lifecycle across several UAE‑based businesses. Based in the UAE, the position offers high visibility, group‑level exposure, and close collaboration with senior finance leadership in a fast‑evolving environment. Client Details Our client is a well‑established international business operating within a highly technical and innovation‑driven industry. With a growing global footprint and diversified operations, the organisation combines structured governance with an entrepreneurial mindset and a strong focus on continuous improvement. Description · Own the end‑to‑end accounting function across multiple UAE entities, ensuring accuracy and consistency · Lead monthly, quarterly, and annual close activities in line with group timelines · Prepare and review management accounts, group reporting packs, and consolidation inputs · Manage intercompany accounting, reconciliations, and eliminations across entities · Ensure full compliance with IFRS and all relevant statutory and regulatory requirements · Act as the main point of contact for external auditors, advisors, and regulatory bodies · Drive improvements in financial controls, processes, and reporting frameworks · Partner closely with the Finance Manager and support the Group CFO on reporting and strategic initiatives · Collaborate with international finance teams to ensure alignment across jurisdictions Profile · 8 to 12+ years of accounting experience within multi‑entity or group environments · Strong technical knowledge of IFRS, group reporting, and consolidations · Proven experience managing audits and external stakeholders · Exposure to UAE and international tax matters is advantageous · Ability to operate effectively in a fast‑paced and evolving business · Strong communication skills and confidence working with senior stakeholders · Professional accounting qualification such as CPA, ACCA, or equivalent preferred · Candidates must be based in the UAE Job Offer · High‑impact role with significant group‑level exposure · Direct access to senior leadership and strategic decision‑making · Opportunity to shape and enhance finance processes within a growing organisation · Collaborative and international working environment | J13: Account Reconciliation, Audit Support, Internal Controls, Regulatory Compliance, CPA, ACCA, Communication, Collaboration, Attention to Detail, Accounting Principles | K13: https://www.bayt.com/en/uae/jobs/senior-accountant-5450962/ | L13: =IF(TRIM(J13)="",0,LEN(J13)-LEN(SUBSTITUTE(J13,",",""))+1) -> 10
A14: 12 | B14: Team Leader | Hertz | Rental & Leasing | Al Futtaim Financial Services | C14: Al Futtaim Group | D14: UAE | E14: Accounting | F14: Bayt | G14: Senior | H14: 2026-04-21 | I14: Job description Overview of the role • To lead and supervise the front-office team at Dubai International Airport. • Ensuring smooth daily operations, exceptional customer service, and achievement of sales and operational targets. • The Team Leader serves as the first line of management, driving performance, maintaining service excellence, and ensuring compliance with company policies in a fast-paced airport environment What you will do Customer Service and Sales : • Ensure high levels of customer satisfaction by delivering a seamless rental experience. • Handle escalated customer issues and complaints promptly and professionally. • Drive upselling of additional products and services (insurance, upgrades, GPS, etc.) to meet revenue targets. Team Leadership • Supervise, train, and support front-office staff (Customer Service Representatives). • Conduct daily briefings, assign duties, and monitor staff schedules to ensure adequate coverage Operational Excellence • Oversee rental processes including check-outs, returns, upgrades, and vehicle exchanges • Ensure all documentation and invoicing are completed accurately and on time. • Monitor vehicle availability and coordinate with the fleet team to minimize wait times. Reporting & Compliance • Track branch KPIs: customer satisfaction, revenue per transaction, upsell ratios, etc. • Prepare daily shift reports and escalate key issues to the Branch Manager. • Ensure data accuracy in rental management systems. • Maintain audit-ready documentation and enforce compliance with internal controls. | J14: Audit Support, Internal Controls, Technical Writing, Customer Experience, Attention to Detail, Deadline Management, Accounting Principles, Sales Operations | K14: https://www.bayt.com/en/uae/jobs/team-leader-hertz-rental-leasing-al-futtaim-financial-services-5440850/ | L14: =IF(TRIM(J14)="",0,LEN(J14)-LEN(SUBSTITUTE(J14,",",""))+1) -> 8
... A2002: 2000 | B2002: Sales Associate | C2002: Pakistan and Emirates Auto spare Parts | D2002: UAE | E2002: Business Administration | F2002: Bayt | G2002: Mid-level | H2002: 2026-03-26 | I2002: Job description SNA Industries, a leading provider of high-quality auto spare parts & Lubricants, is looking for a dynamic and results-driven Sales Person (Both Male & Female) to join our team. The ideal candidate will have experience in the auto spare parts industry and a strong ability to build and maintain customer relationships. Key Responsibilities: Identify and develop new sales opportunities within the auto spare parts market. Build and maintain strong relationships with customers Provide expert advice to customers on product selection and compatibility. Achieve sales targets by promoting and selling our range of spare parts. Handle customer inquiries, process orders, and ensure timely deliveries. Coordinate with the logistics and inventory team to ensure product availability. Salary = 2000 AED + Commission Vehicle and accommodation will be provided Job Type: Full-time Work Location: In person | J2002: Inventory Accounting, Deadline Management, Sales Operations | K2002: https://www.bayt.com/en/uae/jobs/sales-associate-5445221/ | L2002: =IF(TRIM(J2002)="",0,LEN(J2002)-LEN(SUBSTITUTE(J2002,",",""))+1) -> 3

Sheet 💼JOB-SUMMARY
A1: 💼 Job Market Intelligence Summary | MENA Region Dataset | AM1: Country | AN1: Junior | AO1: Mid-level | AP1: Senior | AQ1: Managerial | AR1: Sector Short | AS1: Demand Score | AU1: Sector | AV1: UAE | AW1: KSA | AX1: Egypt | AY1: Jordan | AZ1: TOTAL | BA1: Demand Score
A2: DATASET OVERVIEW | AM2: UAE | AN2: 47 | AO2: 366 | AP2: 182 | AQ2: 252 | AR2: Accounting | AS2: 713 | AU2: Accounting | AV2: 103 | AW2: 62 | AX2: 62 | AY2: 13 | AZ2: =SUM(AV2:AY2) -> 240 | BA2: =ROUND(AZ2/2000*1000,0) -> 120
A3: 💼 Total Jobs | E3: 🏢 Sectors | I3: 🌍 Countries | M3: 🧠 Overall Market Unique Skills | Q3: 📅 Avg Skills/Job sector | U3: 🔗 Shared Skills | AM3: KSA | AN3: 16 | AO3: 234 | AP3: 107 | AQ3: 143 | AR3: Business Admin | AS3: 617 | AU3: Business Admin | AV3: 170 | AW3: 67 | AX3: 63 | AY3: 39 | AZ3: =SUM(AV3:AY3) -> 339 | BA3: =ROUND(AZ3/2000*1000,0) -> 170
A4: 2000 | E4: 8 | I4: 4 | M4: 302 | Q4: 7.65 | U4: 13 | AM4: Egypt | AN4: 19 | AO4: 227 | AP4: 141 | AQ4: 113 | AR4: BI | AS4: 416 | AU4: BI | AV4: 74 | AW4: 63 | AX4: 63 | AY4: 5 | AZ4: =SUM(AV4:AY4) -> 205 | BA4: =ROUND(AZ4/2000*1000,0) -> 103
A5: ━━━━━━━━━━━━━━ | E5: ━━━━━━━━━━━━━━ | I5: ━━━━━━━━━━━━━━ | M5: ━━━━━━━━━━━━━━ | Q5: ━━━━━━━━━━━━━━ | U5: ━━━━━━━━━━━━━━ | AM5: Jordan | AN5: 2 | AO5: 78 | AP5: 39 | AQ5: 34 | AR5: Computer Science | AS5: 539 | AU5: Computer Science | AV5: 69 | AW5: 51 | AX5: 62 | AY5: 13 | AZ5: =SUM(AV5:AY5) -> 195 | BA5: =ROUND(AZ5/2000*1000,0) -> 98
AR6: Cybersecurity | AS6: 492 | AU6: Cybersecurity | AV6: 97 | AW6: 64 | AX6: 63 | AY6: 14 | AZ6: =SUM(AV6:AY6) -> 238 | BA6: =ROUND(AZ6/2000*1000,0) -> 119
AR7: Data Science | AS7: 776 | AU7: Data Science | AV7: 170 | AW7: 68 | AX7: 63 | AY7: 47 | AZ7: =SUM(AV7:AY7) -> 348 | BA7: =ROUND(AZ7/2000*1000,0) -> 174
A8: 📋 Data Quality Report | J8: 📋 Sector × Location Comparison — Jobs & Skills | AR8: Marketing | AS8: 504 | AU8: Marketing | AV8: 93 | AW8: 63 | AX8: 62 | AY8: 14 | AZ8: =SUM(AV8:AY8) -> 232 | BA8: =ROUND(AZ8/2000*1000,0) -> 116
A9: Check | C9: UAE | D9: KSA | E9: Egypt | F9: JORDAN | G9: Overall | H9: Status | AR9: SW Engineering | AS9: 560 | AU9: SW Engineering | AV9: 71 | AW9: 62 | AX9: 62 | AY9: 8 | AZ9: =SUM(AV9:AY9) -> 203 | BA9: =ROUND(AZ9/2000*1000,0) -> 102
A10: Null Skills | C10: 0 | D10: 0 | E10: 0 | F10: =C10+D10+E10 -> 0 | G10: =C10+D10+E10+F10 -> 0 | H10: ✅ Clean
A11: Null Titles | C11: 0 | D11: 0 | E11: 0 | F11: =C11+D11+E11 -> 0 | G11: =C11+D11+E11+F11 -> 0 | H11: ✅ Clean
A12: Null Companies | C12: 3 | D12: 9 | E12: 2 | F12: 3 | G12: =C12+D12+E12+F12 -> 17 | H12: ⚠ Issues
A13: SHARED SKILLS (13): These 13 skills appeared in job postings across all 8 job sectors in the dataset: Communication, Collaboration, Attention to Detail, Problem Solving, Deadline Management, Standards Management, Technical Writing, Data Analysis, Audit Support, Regulatory Compliance, Customer Experience, Budgeting, and Vendor Management. This means employers across all sectors consistently require these skills, regardless of the job type or industry.
A17: 📊 Job Market Dataset — Summary Statistics
A18: Metric | D18: UAE | E18: KSA | F18: Egypt | G18: Jordan
A19: Total Jobs | D19: 847 | E19: 500 | F19: 500 | G19: 153
A20: Sectors Covered | D20: 8 | E20: 8 | F20: 8 | G20: 8
A21: Country-Level Unique Skills | D21: 145 | E21: 127 | F21: 115 | G21: 114
J22: TOTALS | K22: 240 | M22: 339 | N22: 205 | O22: 195 | Q22: 238 | R22: 348 | T22: 232 | V22: 203
A23: 🏆 SECTOR PROFILE SUMMARY
A24: 💰 Accounting & Finance | Q24: 📊 Data Science & AI
A25: Highest avg skills/job:11.3 — most demanding sector | Q25: Largest sector by volume: 348 jobs across MENA
A26: Top skills: Accounting Principles · Audit Support · Attention to Detail | Q26: Broadest skill diversity: 154 unique skills identified
A27: ERP Systems: 84 postings · Excel: 86 · VAT: 39 | Q27: Collaboration (200 postings) + Software Development (169 postings) — top 2 demanded
A30: 📈 Visual Analytics Dashboard - Job Market Intelligence - MENA Region
A45: Sector | B45: Jobs | D45: Sector | E45: Unique Skills | F45: Avg Skills/Job | H45: Location | I45: Jobs
A46: Accounting | B46: 240 | D46: Accounting | E46: 72 | F46: 11.3 | H46: UAE | I46: 847
A47: Business Administration | B47: 339 | D47: Business Administration | E47: 107 | F47: 5.2 | H47: Saudi Arabia | I47: 500
A48: Business Intelligence | B48: 205 | D48: Business Intelligence | E48: 85 | F48: 7 | H48: Egypt | I48: 500
A49: Computer Science | B49: 195 | D49: Computer Science | E49: 89 | F49: 9.8 | H49: Jordan | I49: 153
A50: Cyber Security | B50: 238 | D50: Cyber Security | E50: 94 | F50: 6.9
A51: Data Science | B51: 348 | D51: Data Science | E51: 136 | F51: 7.3
A52: E-Marketing & Digital Mktg | B52: 232 | D52: E-Marketing & Digital Mktg | E52: 71 | F52: 5.4
A53: Software Engineering | B53: 203 | D53: Software Engineering | E53: 94 | F53: 7.8

Sheet 📖 Synonym- Dictionary
A1: 📖 Skill Synonym Dictionary · Job Market ↔ University Curriculum · 54 Skills
A2: Maps job market skill labels (industry terms) to university curriculum equivalents. Every synonym term is verified to exist exactly in the UNI-DATASET skill set. Used to compute Skill Alignment % in the Dashboard.
A3: 📋 Job Skills Mapped: 54 · 🔗 Total Synonym Terms: 158 · ✅ All terms verified against UNI-DATASET
A4: # | B4: Job Market Skill (Industry Term) | C4: University Curriculum Equivalents (Academic Terms) | D4: Category
A5: ▌ Soft Skills
A6: 1 | B6: Collaboration | C6: Communication Skills · Business Communication · Technical Writing Communication Skills | D6: Soft Skills
A7: 2 | B7: Technical Writing | C7: Technical Writing Communication Skills · Research Methods · Business Communication | D7: Soft Skills
A8: 3 | B8: Attention to Detail | C8: Software Quality Assurance · Total Quality Management · Auditing | D8: Soft Skills
A9: 4 | B9: Deadline Management | C9: Strategic Planning · Project Management · IT Project Management | D9: Soft Skills
A10: 5 | B10: Organizational Skills | C10: Strategic Planning · Operations Research · Production and Operations Management | D10: Soft Skills
A11: 6 | B11: Customer Experience | C11: Customer Relationship Management · Digital Consumer Behavior · Services Marketing | D11: Soft Skills
A12: 7 | B12: English Language | C12: English Language Skills for BI · Business English · Business Communication | D12: Soft Skills
A13: ▌ Technology
A14: 8 | B14: Software Development | C14: Software Engineering Principles · Software Development · Software Development Life Cycle · Systems Analysis and Design · Object-oriented Programming | D14: Technology
A15: 9 | B15: AI/ML | C15: Machine Learning · Artificial Intelligence · Deep Learning · Artificial Intelligence in Business · Natural Language Processing | D15: Technology
A16: 10 | B16: Agile Methodology | C16: Agile Methodology · Scrum · Software Development Life Cycle | D16: Technology
A17: 11 | B17: CI/CD | C17: DevOps · Software Configuration Management · Version Control | D17: Technology
A18: 12 | B18: Microsoft Azure | C18: Cloud Computing · Cloud Security | D18: Technology
A19: 13 | B19: AWS | C19: Cloud Computing · Cloud Security · High Performance Computing | D19: Technology
A20: 14 | B20: REST APIs | C20: Web Programming · Api Design · Internet of Things | D20: Technology
A21: 15 | B21: Backend Development | C21: Web Programming · Object-oriented Programming · Systems Programming | D21: Technology
A22: 16 | B22: Microsoft Excel | C22: Microsoft Excel · Spreadsheet Management · VBA Programming | D22: Technology
A23: 17 | B23: Microsoft Office | C23: Computer Applications · Microsoft Excel · Microsoft Access | D23: Technology
A24: 18 | B24: ERP Systems | C24: Enterprise Resource Planning · SAP ERP | D24: Technology
A25: 19 | B25: SAP | C25: SAP ERP · Enterprise Resource Planning | D25: Technology
... A37: 31 | B37: UX/UI Principles | C37: UI/UX Design · Web Design · Human Computer Interaction | D37: Technology
A38: ▌ Business
A39: 32 | B39: Project Management | C39: Project Management · IT Project Management · Software Development Life Cycle · Strategic Planning | D39: Business
A40: 33 | B40: Standards Management | C40: Total Quality Management · Software Quality Assurance · IFRS Standards | D40: Business
A41: 34 | B41: Regulatory Compliance | C41: Commercial Law · Business Ethics and Legislation · Tax Accounting | D41: Business
A42: 35 | B42: Product Management | C42: New Product Development · Marketing Management · Brand Management | D42: Business
A43: 36 | B43: Business Analysis | C43: Statistical Analysis · Data Analytics · Business Intelligence · Marketing Research | D43: Business
A44: 37 | B44: Vendor Management | C44: Supply Chain Management · Distribution Channel Management · Operations Research | D44: Business
A45: 38 | B45: Sales Operations | C45: Sales Management · Marketing Principles · Marketing Management | D45: Business
A46: 39 | B46: Cost Control | C46: Cost Accounting · Budgeting · Financial Management · Advanced Cost Accounting | D46: Business
A47: ▌ Accounting
A48: 40 | B48: Audit Support | C48: Auditing · Internal Auditing · Forensic Accounting | D48: Accounting
A49: 41 | B49: Financial Reporting | C49: Financial Statements · Financial Statement Analysis · IFRS Standards · Financial Analysis | D49: Accounting
A50: 42 | B50: Account Reconciliation | C50: Accounts Receivable Management · Financial Ratio Analysis | D50: Accounting
A51: 43 | B51: Internal Controls | C51: Auditing · Internal Auditing · Accounting Theory | D51: Accounting
...

Sheet 📖 Synonym Dictionary
A1: 📖 Skill Synonym Dictionary · Job Market ↔ University Curriculum · 54 Skills | 209 Mappings
A2: This dictionary maps job market skill labels to their equivalent terms in university curricula. Built manually to resolve naming inconsistencies between industry and academic vocabulary. Used to compute the corrected Skill Alignment % in the DASHBOARD sheet.
A3: 📋 Total Job Skills Mapped: 54 | B3: 🔗 Total Synonym Mappings: 209 | C3: 📊 Method: Manual keyword matching + expert review
A4: # | B4: Job Market Skill (Industry Term) | C4: University Curriculum Equivalents (Academic Terms) | D4: Category
A5: ▌ Soft Skills
A6: 1 | B6: Collaboration | C6: Teamwork · Team Collaboration · Group Work · Collaborative Work · Team Projects | D6: Soft Skills
A7: 2 | B7: Technical Writing | C7: Technical Writing For Software Engineers · Report Writing · Documentation · Written Communication | D7: Soft Skills
A8: 3 | B8: Attention to Detail | C8: Accuracy · Precision · Quality Assurance · Detail-oriented Work | D8: Soft Skills
A9: 4 | B9: Deadline Management | C9: Time Management · Project Scheduling · Scheduling · Planning | D9: Soft Skills
A10: 5 | B10: Organizational Skills | C10: Planning · Organization · Administrative Skills | D10: Soft Skills
A11: 6 | B11: Customer Experience | C11: Customer Service · Electronic Customer Experience · Enhancing Customer Experience Through Web Design · Customer Relationship Management | D11: Soft Skills
A12: 7 | B12: English Language | C12: English Language Skills For Business Intelligence Professionals · Business English · Technical English | D12: Soft Skills
A13: ▌ Technology
A14: 8 | B14: Software Development | C14: Software Engineering · Programming · Systems Development · Application Development · Software Design | D14: Technology
A15: 9 | B15: AI/ML | C15: Machine Learning · ML · Artificial Intelligence · Deep Learning · AI · AI Applications · AI Fundamentals · AI Techniques In Intelligent Systems | D15: Technology
A16: 10 | B16: Agile Methodology | C16: Agile · Scrum Methodology · Agile Development · Scrum · Agile Project Management | D16: Technology
A17: 11 | B17: CI/CD | C17: DevOps · Continuous Integration · Deployment Automation · Pipeline Automation | D17: Technology
A18: 12 | B18: Microsoft Azure | C18: Cloud Computing · Cloud Platforms · Azure · Cloud Services | D18: Technology
A19: 13 | B19: AWS | C19: Cloud Computing · Amazon Web Services · Cloud Platforms | D19: Technology
A20: 14 | B20: REST APIs | C20: API Development · Web Services · API Integration · RESTful Services · Web APIs | D20: Technology
A21: 15 | B21: Backend Development | C21: Server-side Programming · Backend Systems · Server Programming | D21: Technology
A22: 16 | B22: Microsoft Excel | C22: Microsoft Excel For Administrative Applications · Microsoft Excel For Accounting · Spreadsheet Analysis · Excel Analysis | D22: Technology
A23: 17 | B23: Microsoft Office | C23: Office Applications · Productivity Tools · MS Office Suite | D23: Technology
A24: 18 | B24: ERP Systems | C24: Enterprise Resource Planning · ERP · SAP · Oracle ERP · Business Information Systems | D24: Technology
A25: 19 | B25: SAP | C25: SAP Systems · ERP Systems · Enterprise Systems | D25: Technology
... A37: 31 | B37: UX/UI Principles | C37: User Experience Design · Interface Design · UI Design · User Interface Design · Human-computer Interaction | D37: Technology
A38: ▌ Business
A39: 32 | B39: Project Management | C39: Project Management Methodologies · Project Planning · Project Budgeting And Risk Management · PMP · Project Scheduling | D39: Business
A40: 33 | B40: Standards Management | C40: Quality Standards · ISO Standards · Compliance Frameworks (ISO 27001) · Quality Management | D40: Business
A41: 34 | B41: Regulatory Compliance | C41: Compliance · Legal Compliance · Tax Compliance · Regulatory Frameworks | D41: Business
A42: 35 | B42: Product Management | C42: Product Design And Pricing Management · Product Development · Product Strategy | D42: Business
A43: 36 | B43: Business Analysis | C43: Business Data Analysis For Decision-making · Statistical Analysis Methods For Business Decision-making · Business Intelligence Analysis | D43: Business
A44: 37 | B44: Vendor Management | C44: Supplier Management · Procurement · Supply Chain Management · Procurement Management | D44: Business
A45: 38 | B45: Sales Operations | C45: Sales Management · Sales Techniques · Marketing And Sales | D45: Business
A46: 39 | B46: Cost Control | C46: Cost Control And Earned Value Management · Determine Cost Control Methods By Collecting And Recording All The Cost Elements · Cost Management · Budgeting | D46: Business
A47: ▌ Accounting
A48: 40 | B48: Audit Support | C48: Internal Controls And Internal Auditing · Auditing Process And Materiality · Auditing · External Auditing · Internal Auditing | D48: Accounting
A49: 41 | B49: Financial Reporting | C49: Financial Statement Preparation (IAS) · Through The Conceptual Framework Upon Which Financial Reporting Is Built · Financial Statements · Financial Analysis | D49: Accounting
A50: 42 | B50: Account Reconciliation | C50: Bank Reconciliation · Account Reconciliation Process · Reconciliation Methods | D50: Accounting
A51: 43 | B51: Internal Controls | C51: Internal Controls And Internal Auditing · Control Systems · Internal Audit Procedures | D51: Accounting
...

Sheet   📊 DASHBOARD
AP1: 🔗 Cross-Analysis Data · Chart Source Data for Dashboard
B2: 🎓 University vs Job Market · DNA Skills Dashboard
AP3: 📊 Top Shared Skills — Market Frequency | AR3: ⚠️ Critical Missing Technical Skills | AT3: 👤 Experience Level Distribution | AV3: Chart Source Data (auto-referenced by charts below):
AP4: Skill | AQ4: Mkt Freq | AR4: Missing Skill | AS4: Mkt Freq | AT4: Experience Level | AU4: Jobs | AV4: Sector | AW4: Jobs | AX4: Demand | AZ4: Major | BA4: Petra | BB4: PSUT | BC4: AZ | BE4: Country | BF4: Jobs | BH4: Major | BI4: Petra% | BJ4: PSUT% | BK4: AZ% | BM4: University | BN4: Skills
AP5: Communication | AQ5: 832 | AR5: Software Development | AS5: 521 | AT5: Mid-level | AU5: 905 | AV5: Accounting | AW5: 240 | AX5: 120 | AZ5: Accounting | BA5: 79 | BB5: 71 | BC5: 208 | BE5: UAE | BF5: 847 | BH5: Accounting | BI5: 14 | BJ5: 11 | BK5: 21 | BM5: U.Petra | BN5: 944
B6: 2000 | H6: 551 | M6: 4 | R6: 3 | X6: 8 | AP6: Problem Solving | AQ6: 540 | AR6: AI/ML | AS6: 309 | AT6: Managerial | AU6: 542 | AV6: Bus.Admin | AW6: 339 | AX6: 170 | AZ6: Bus.Admin | BA6: 265 | BB6: 114 | BC6: 119 | BE6: KSA | BF6: 500 | BH6: Bus.Admin | BI6: 16 | BJ6: 14 | BK6: 11 | BM6: PSUT | BN6: 1147
AP7: Accounting Principles | AQ7: 438 | AR7: Project Management | AS7: 235 | AT7: Senior | AU7: 469 | AV7: Bus.Intel | AW7: 205 | AX7: 102 | AZ7: Bus.Intel | BA7: 92 | BB7: 0 | BC7: 49 | BE7: Egypt | BF7: 500 | BH7: Bus.Intel | BI7: 11 | BJ7: 0 | BK7: 12 | BM7: Al-Zaytoonah | BN7: 1315
B8: 💼 Total Jobs | H8: 📖 Total Courses | M8: 🌍 MENA Countries | R8: 🏫 Universities | X8: 🎓 Majors | AP8: Budgeting | AQ8: 374 | AR8: Agile Methodology | AS8: 164 | AT8: Junior | AU8: 84 | AV8: Comp.Sci | AW8: 195 | AX8: 98 | AZ8: Comp.Sci | BA8: 101 | BB8: 384 | BC8: 222 | BE8: Jordan | BF8: 153 | BH8: Comp.Sci | BI8: 7 | BJ8: 19 | BK8: 13
AP9: Audit Support | AQ9: 354 | AR9: Cybersecurity | AS9: 133 | AV9: CyberSec | AW9: 238 | AX9: 119 | AZ9: CyberSec | BA9: 141 | BB9: 251 | BC9: 191 | BH9: CyberSec | BI9: 12 | BJ9: 13 | BK9: 15
B10: 📊 Job Market Demand by Sector — MENA Region ( 2,000 Jobs ) | M10: 🎓 University Curriculum Analysis - Skills & Courses per Major | Y10: ⚠️ Critical Skill Gaps — Top Missing Skill / Underrepresented Skill per Major | AP10: Data Analysis | AQ10: 325 | AR10: CI/CD | AS10: 127 | AV10: Data Science | AW10: 348 | AX10: 174 | AZ10: Data Sci | BA10: 115 | BB10: 212 | BC10: 144 | BH10: Data Sci | BI10: 4 | BJ10: 10 | BK10: 9
B11: Sector | C11: UAE | D11: KSA | E11: Egypt | F11: Jordan | G11: Total Job Postings | H11: Sector-Level Unique Skills | I11: Avg Skills / Job | J11: Demand Score | K11: Demand Level | M11: Major | N11: Petra Skills | O11: PSUT Skills | P11: ZUJ Skills | Q11: Petra Courses | R11: PSUT Courses | S11: ZUJ Courses | T11: Total Major-Level Skills | U11: Total Courses | V11: Density S/C | Y11: Sector / Major | Z11: Top Unmatched Market Skill | AA11: Job Postings Demanding | AP11: AI/ML | AQ11: 309 | AR11: Microsoft Azure | AS11: 121 | AV11: E-Marketing | AW11: 232 | AX11: 116 | AZ11: Marketing | BA11: 61 | BB11: 98 | BC11: 201 | BH11: E-Mktg | BI11: 8 | BJ11: 8 | BK11: 10
B12: Accounting | C12: 103 | D12: 62 | E12: 62 | F12: 13 | G12: =F12+E12+D12+C12 -> 240 | H12: 72 | I12: =ROUND(AVERAGEIF('💼JOB-DATASET'!$E:$E,$B12,'💼JOB-DATASET'!$L:$L),1) -> 11.4 | J12: =ROUND(G12/2000*1000,0) -> 120 | K12: =IF(J12>=160,"🔴 TOP",IF(J12>=130,"🟢 HIGH",IF(J12>=100,"🟡 MED","⚪ LOW"))) -> 🟡 MED | M12: Accounting | N12: 79 | O12: 71 | P12: 208 | Q12: 14 | R12: 17 | S12: 21 | T12: =P12+O12+N12 -> 358 | U12: =S12+R12+Q12 -> 52 | V12: =T12/U12 -> 6.8846154 | Y12: Accounting | Z12: Bank Reconciliation | AA12: 27 | AP12: Microsoft Excel | AQ12: 270 | AR12: AWS | AS12: 120 | AV12: SW Eng | AW12: 203 | AX12: 102 | AZ12: SW Eng | BA12: 110 | BB12: 101 | BC12: 214 | BH12: SW Eng | BI12: 22 | BJ12: 9 | BK12: 17
B13: Business Administration | C13: 170 | D13: 67 | E13: 63 | F13: 39 | G13: =F13+E13+D13+C13 -> 339 | H13: 107 | I13: =ROUND(AVERAGEIF('💼JOB-DATASET'!$E:$E,$B13,'💼JOB-DATASET'!$L:$L),1) -> 5.4 | J13: =ROUND(G13/2000*1000,0) -> 170 | K13: =IF(J13>=160,"🔴 TOP",IF(J13>=130,"🟢 HIGH",IF(J13>=100,"🟡 MED","⚪ LOW"))) -> 🔴 TOP | M13: Business Admin | N13: 265 | O13: 114 | P13: 119 | Q13: 44 | R13: 25 | S13: 36 | T13: =P13+O13+N13 -> 498 | U13: =S13+R13+Q13 -> 105 | V13: =T13/U13 -> 4.7428571 | Y13: Business Administration | Z13: AI/ML | AA13: 31 | AP13: Forecasting | AQ13: 254 | AR13: REST APIs | AS13: 104
B14: Business Intelligence | C14: 74 | D14: 63 | E14: 63 | F14: 5 | G14: =F14+E14+D14+C14 -> 205 | H14: 85 | I14: =ROUND(AVERAGEIF('💼JOB-DATASET'!$E:$E,$B14,'💼JOB-DATASET'!$L:$L),1) -> 7 | J14: =ROUND(G14/2000*1000,0) -> 103 | K14: =IF(J14>=160,"🔴 TOP",IF(J14>=130,"🟢 HIGH",IF(J14>=100,"🟡 MED","⚪ LOW"))) -> 🟡 MED | M14: Business Intelligence | N14: 92 | O14: 0 | P14: 49 | Q14: 18 | R14: 0 | S14: 33 | T14: =P14+O14+N14 -> 141 | U14: =S14+R14+Q14 -> 51 | V14: =T14/U14 -> 2.7647059 | Y14: Business Intelligence | Z14: AI/ML | AA14: 45 | AP14: Project Management | AQ14: 235 | AR14: Backend Development | AS14: 101
B15: Computer Science | C15: 69 | D15: 51 | E15: 62 | F15: 13 | G15: =F15+E15+D15+C15 -> 195 | H15: 89 | I15: =ROUND(AVERAGEIF('💼JOB-DATASET'!$E:$E,$B15,'💼JOB-DATASET'!$L:$L),1) -> 9.8 | J15: =ROUND(G15/2000*1000,0) -> 98 | K15: =IF(J15>=160,"🔴 TOP",IF(J15>=130,"🟢 HIGH",IF(J15>=100,"🟡 MED","⚪ LOW"))) -> ⚪ LOW | M15: Computer Science | N15: 101 | O15: 384 | P15: 222 | Q15: 17 | R15: 46 | S15: 29 | T15: =P15+O15+N15 -> 707 | U15: =S15+R15+Q15 -> 92 | V15: =T15/U15 -> 7.6847826 | Y15: Computer Science | Z15: Software Development | AA15: 156 | AR15: UX/UI Principles | AS15: 89
B16: Cyber Security | C16: 97 | D16: 64 | E16: 63 | F16: 14 | G16: =F16+E16+D16+C16 -> 238 | H16: 94 | I16: =ROUND(AVERAGEIF('💼JOB-DATASET'!$E:$E,$B16,'💼JOB-DATASET'!$L:$L),1) -> 6.9 | J16: =ROUND(G16/2000*1000,0) -> 119 | K16: =IF(J16>=160,"🔴 TOP",IF(J16>=130,"🟢 HIGH",IF(J16>=100,"🟡 MED","⚪ LOW"))) -> 🟡 MED | M16: Cybersecurity | N16: 141 | O16: 251 | P16: 191 | Q16: 22 | R16: 30 | S16: 22 | T16: =P16+O16+N16 -> 583 | U16: =S16+R16+Q16 -> 74 | V16: =T16/U16 -> 7.8783784 | Y16: Cyber Security | Z16: Cybersecurity | AA16: 80 | AR16: Kubernetes | AS16: 79
B17: Data Science | C17: 170 | D17: 68 | E17: 63 | F17: 47 | G17: =F17+E17+D17+C17 -> 348 | H17: 136 | I17: =ROUND(AVERAGEIF('💼JOB-DATASET'!$E:$E,$B17,'💼JOB-DATASET'!$L:$L),1) -> 7.4 | J17: =ROUND(G17/2000*1000,0) -> 174 | K17: =IF(J17>=160,"🔴 TOP",IF(J17>=130,"🟢 HIGH",IF(J17>=100,"🟡 MED","⚪ LOW"))) -> 🔴 TOP | M17: Data Science & AI | N17: 115 | O17: 212 | P17: 144 | Q17: 17 | R17: 36 | S17: 21 | T17: =P17+O17+N17 -> 471 | U17: =S17+R17+Q17 -> 74 | V17: =T17/U17 -> 6.3648649 | Y17: Data Science | Z17: Software Development | AA17: 169
B18: E-Marketing & Digital Marketing | C18: 93 | D18: 63 | E18: 62 | F18: 14 | G18: =F18+E18+D18+C18 -> 232 | H18: 71 | I18: =ROUND(AVERAGEIF('💼JOB-DATASET'!$E:$E,$B18,'💼JOB-DATASET'!$L:$L),1) -> 5.5 | J18: =ROUND(G18/2000*1000,0) -> 116 | K18: =IF(J18>=160,"🔴 TOP",IF(J18>=130,"🟢 HIGH",IF(J18>=100,"🟡 MED","⚪ LOW"))) -> 🟡 MED | M18: Marketing | N18: 61 | O18: 98 | P18: 201 | Q18: 10 | R18: 22 | S18: 35 | T18: =P18+O18+N18 -> 360 | U18: =S18+R18+Q18 -> 67 | V18: =T18/U18 -> 5.3731343 | Y18: E-Marketing & Digital Mktg | Z18: Project Management | AA18: 39
B19: Software Engineering | C19: 71 | D19: 62 | E19: 62 | F19: 8 | G19: =F19+E19+D19+C19 -> 203 | H19: 94 | I19: =ROUND(AVERAGEIF('💼JOB-DATASET'!$E:$E,$B19,'💼JOB-DATASET'!$L:$L),1) -> 7.8 | J19: =ROUND(G19/2000*1000,0) -> 102 | K19: =IF(J19>=160,"🔴 TOP",IF(J19>=130,"🟢 HIGH",IF(J19>=100,"🟡 MED","⚪ LOW"))) -> 🟡 MED | M19: SW Engineering | N19: 110 | O19: 101 | P19: 214 | Q19: 19 | R19: 22 | S19: 27 | T19: =P19+O19+N19 -> 425 | U19: =S19+R19+Q19 -> 68 | V19: =T19/U19 -> 6.25 | Y19: Software Engineering | Z19: Software Development | AA19: 153
B20: 📌 GRAND TOTAL | C20: =SUM(C12:C19) -> 847 | D20: =SUM(D12:D19) -> 500 | E20: =SUM(E12:E19) -> 500 | F20: =SUM(F12:F19) -> 153 | G20: =SUM(G12:G19) -> 2000 | H20: =SUM(H12:H19) -> 748 | I20: =AVERAGE(I12:I19) -> 7.65 | J20: =MAX(J12:J19) -> 174 | M20: 📌 TOTALS | N20: =SUM(N12:N19) -> 964 | O20: =SUM(O12:O19) -> 1231 | P20: =SUM(P12:P19) -> 1348 | Q20: =SUM(Q12:Q19) -> 161 | R20: =SUM(R12:R19) -> 198 | S20: =SUM(S12:S19) -> 224 | T20: =SUM(T12:T19) -> 3543 | U20: =SUM(U12:U19) -> 583 | V20: =AVERAGE(V12:V19) -> 5.9929173
E23: Smart Insights
E24: 🏆 PSUT leads in IT curriculum volume — CS: 384 skills · Cybersecurity: 251 · Data Science: 212
E25: 📈 Data Science: #1 sector — 348 jobs · 7.3 avg skills/job · 136 unique skills
E26: ⚠️ AI/ML in 309 job postings (15.4%) — Not coverd enough in all 3 university curricula
E27: 🌍 UAE: 847 of 2,000 jobs (42%) · KSA: 500 · Egypt: 500 · Jordan: 153
E28: 🎓 Al-Zaytoonah: 1315 unique skills · 214 courses — broadest curriculum among the 3 universities
E29: 📊 Accounting jobs require the highest average number of skills per posting: 11.4 skills across 240 job postings.
B35: 📈 Visual Analytics — Interactive Charts
B66: 📋 Data Sources: MENA Job Market — 2,000 Postings (Bayt.com) × Jordan University Curriculum — 3,692 Records | Universities: Petra · PSUT · Al-Zaytoonah | MENA: UAE · KSA · Egypt · Jordan

Sheet 📊ChartData
A1: Major | B1: U. Petra | C1: PSUT | D1: Al-Zaytoonah | F1: Major | G1: U. Petra | H1: PSUT | I1: Al-Zaytoonah | K1: University | L1: Courses | M1: Skills | N1: Entries | P1: Major | Q1: U. Petra | R1: PSUT | S1: Al-Zaytoonah | U1: Major | V1: Petra | W1: PSUT | X1: AZ | Z1: Group | AA1: Count
A2: Accounting | B2: 79 | C2: 71 | D2: 208 | F2: Accounting | G2: 14 | H2: 17 | I2: 21 | K2: U. Petra | L2: 158 | M2: 944 | N2: 1008 | P2: Accounting | Q2: 5.6 | R2: 4.2 | S2: 9.9 | U2: Accounting | V2: 79 | W2: 71 | X2: 208 | Z2: Petra only | AA2: 823
A3: Bus. Admin | B3: 265 | C3: 114 | D3: 119 | F3: Bus. Admin | G3: 44 | H3: 25 | I3: 36 | K3: PSUT | L3: 179 | M3: 1147 | N3: 1271 | P3: Bus. Admin | Q3: 6 | R3: 4.6 | S3: 3.3 | U3: Bus. Admin | V3: 265 | W3: 114 | X3: 119 | Z3: PSUT only | AA3: 1027
A4: Bus. Intel. | B4: 92 | C4: 0 | D4: 49 | F4: Bus. Intel. | G4: 18 | H4: 0 | I4: 33 | K4: Al-Zaytoonah | L4: 214 | M4: 1315 | N4: 1413 | P4: Bus. Intel. | Q4: 5.1 | R4: 0 | S4: 1.5 | U4: Bus. Intel. | V4: 92 | W4: 0 | X4: 49 | Z4: AZ only | AA4: 1194
A5: Comp. Sci. | B5: 101 | C5: 384 | D5: 222 | F5: Comp. Sci. | G5: 17 | H5: 46 | I5: 29 | P5: Comp. Sci. | Q5: 5.9 | R5: 8.3 | S5: 7.7 | U5: Comp. Sci. | V5: 101 | W5: 384 | X5: 222 | Z5: Petra∩PSUT | AA5: 46
A6: Cybersecurity | B6: 141 | C6: 251 | D6: 191 | F6: Cybersecurity | G6: 22 | H6: 30 | I6: 22 | P6: Cybersecurity | Q6: 6.4 | R6: 8.4 | S6: 8.7 | U6: Cybersecurity | V6: 141 | W6: 251 | X6: 191 | Z6: Petra∩AZ | AA6: 47
